Workbook
Name _col2: '[2]Kas $'!#REF!
Name _TGL1: #REF!
Name _TGL2: #REF!
Name ALAMAT: #REF!
Name Daftarkaryawan: #REF!
Name DINO: [3]data!$P$3:$R$9
Name Excel_BuiltIn__FilterDatabase_1: #REF!
Name Excel_BuiltIn__FilterDatabase_2: #REF!
Name Excel_BuiltIn__FilterDatabase_3_1: #REF!
Name Excel_BuiltIn__FilterDatabase_4: #REF!
Name Excel_BuiltIn__FilterDatabase_5: #REF!
Name Excel_BuiltIn_Print_Area: "$#REF!.$C$1:$R$37"
Name Excel_BuiltIn_Print_Area_1: #REF!
Name Excel_BuiltIn_Print_Area_1_1: #REF!
Name Excel_BuiltIn_Print_Area_1_1_1: #REF!
Name Excel_BuiltIn_Print_Area_1_1_1_1: (#REF!,#REF!)
Name Excel_BuiltIn_Print_Area_1_1_1_1_1: #REF!
Name Excel_BuiltIn_Print_Area_10_1: #REF!
Name Excel_BuiltIn_Print_Area_11_1: #REF!
Name Excel_BuiltIn_Print_Area_12_1: #REF!
Name Excel_BuiltIn_Print_Area_13: #REF!
Name Excel_BuiltIn_Print_Area_13_1: #REF!
Name Excel_BuiltIn_Print_Area_14_1: #REF!
Name Excel_BuiltIn_Print_Area_14_1_1: #REF!
Name Excel_BuiltIn_Print_Area_14_1_1_1: #REF!
Name Excel_BuiltIn_Print_Area_15_1: #REF!
Name Excel_BuiltIn_Print_Area_16: #REF!
Name Excel_BuiltIn_Print_Area_16_1: #REF!
Name Excel_BuiltIn_Print_Area_17_1: #REF!
Name Excel_BuiltIn_Print_Area_18_1: #REF!
Name Excel_BuiltIn_Print_Area_19_1: #REF!
Name Excel_BuiltIn_Print_Area_2: #REF!
Name Excel_BuiltIn_Print_Area_2_1: #REF!
Name Excel_BuiltIn_Print_Area_20_1: #REF!
Name Excel_BuiltIn_Print_Area_3: #REF!
Name Excel_BuiltIn_Print_Area_3_1: #REF!
Name Excel_BuiltIn_Print_Area_4: #REF!
Name Excel_BuiltIn_Print_Area_4_1: #REF!
Name Excel_BuiltIn_Print_Area_5: '[4]1771_III'!#REF!
Name Excel_BuiltIn_Print_Area_5_1: #REF!
Name Excel_BuiltIn_Print_Area_6_1: #REF!
Name Excel_BuiltIn_Print_Area_7_1: #REF!
Name Excel_BuiltIn_Print_Area_8_1: #REF!
Name Excel_BuiltIn_Print_Area_9: #REF!
Name Excel_BuiltIn_Print_Area_9_1: #REF!
Name Excel_BuiltIn_Print_Titles_1_1: #REF!
Name Excel_BuiltIn_Print_Titles_1_1_1: #REF!
Name Excel_BuiltIn_Print_Titles_2: #REF!
Name Excel_BuiltIn_Print_Titles_2_1: #REF!
Name Excel_BuiltIn_Print_Titles_3: #REF!
Name Excel_BuiltIn_Print_Titles_3_1: #REF!
Name Excel_BuiltIn_Print_Titles_4: #REF!
Name Excel_BuiltIn_Print_Titles_4_1: #REF!
Name JUMLAH: #REF!
Name kd: '[2]Kas $'!#REF!
Name kode_akun: '[5]Saldo Awal'!$B$9:$B$48
Name KODE_KPP: [6]KODE!$A$1:$B$196
Name kodewp: #REF!
Name KOTA: #REF!
Name KPP: #REF!

Sheet Daftar Gaji
A1: PT MITRA KARYA SARANA
A4: NO | B4: NAMA | C4: Email | D4: NPWP | E4: NIK | F4: ALAMAT | G4: JABATAN | H4: STS | I4: MASA KERJA | K4: GAJI POKOK | L4: TUNJANGAN | M4: LEMBUR | N4: ABSEN | O4: JKK | P4: JPK | Q4: JKM | R4: THR | S4: JHT+JP | T4: PENGHASILAN BRUTO | U4: KATEGORI | V4: TARIF | W4: PAJAK | Y4: JHT+JP | Z4: JPK | AA4: PPH 21 SEBULAN | AB4: NET SALARY | AD4: RoundUp | AE4: Deduct | AF4: Take Home Pay
O5: 0.0089 | P5: 4% | Q5: 0.3% | S5: 5.7% | Y5: 3% | Z5: 1% | AD5: Salary
A6: 1 | B6: WAWAN MUNANDAR | C6: herliana_81@yahoo.co.id | D6: 72.832.315.5-215.000 | E6: 2171101011769010 | F6: Batam | G6: Supervisor | H6: K1 | I6: 1 | J6: 12 | K6: =wawan!E14 -> 5000000 | L6: =wawan!E15+wawan!E16+wawan!E21 -> 570000 | M6: =SUM(wawan!E17:F20) -> 3065896 | N6: =-(wawan!K14+wawan!K18) -> 0 | O6: =0.89%*10164000 -> 90459.6 | P6: =4%*10164000 -> 406560 | Q6: =0.3%*10164000 -> 30492 | S6: =5.7%*10164000 -> 579348 | T6: =ROUND(SUM(K6:R6),0) -> 9163408 | U6: =IFERROR(VLOOKUP(H6,TER!$B$4:$D$15,2,FALSE),"") -> B | V6: =SUMPRODUCT(TER!$K$4:$K$130*(TER!$G$4:$G$130=U6)*(TER!$H$4:$H$130<T6)*((TER!$J$4:$J$130>=T6)+(TER!$J$4:$J$130=""))) -> 0.01 | W6: =IFERROR(ROUND(T6*V6,0),"") -> 91634 | Y6: =wawan!K16 -> 304920 | Z6: =wawan!K19 -> 101640 | AA6: =W6 -> 91634 | AB6: =T6-SUM(O6:Q6)-Y6-AA6-Z6 -> 8137702.4 | AD6: =ROUNDUP(AB6,-3) -> 8138000 | AE6: =wawan!K17 -> 0 | AF6: =SUM(AD6:AE6) -> 8138000 | AG6: =AF6-R6 -> 8138000
A7: 2 | B7: HARJONO | C7: herliana_81@yahoo.co.id | D7: 95.453.012.7-225.000 | E7: 2171101004849010 | F7: Batam | G7: Leader | H7: K2 | I7: 1 | J7: 12 | K7: =harjono!E14 -> 3000000 | L7: =harjono!E15+harjono!E16+harjono!E21 -> 570000 | M7: =SUM(harjono!E17:F20) -> 358381.5 | N7: =-(harjono!K14+harjono!K18) -> 0 | O7: =0.89%*K7 -> 26700 | P7: =4%*K7 -> 120000 | Q7: =0.3%*K7 -> 9000 | S7: =5.7%*K7 -> 171000 | T7: =ROUND(SUM(K7:R7),0) -> 4084082 | U7: =IFERROR(VLOOKUP(H7,TER!$B$4:$D$15,2,FALSE),"") -> B | V7: =SUMPRODUCT(TER!$K$4:$K$130*(TER!$G$4:$G$130=U7)*(TER!$H$4:$H$130<T7)*((TER!$J$4:$J$130>=T7)+(TER!$J$4:$J$130=""))) -> 0 | W7: =IFERROR(ROUND(T7*V7,0),"") -> 0 | Y7: =harjono!K16 -> 90000 | Z7: =harjono!K19 -> 30000 | AA7: =W7 -> 0 | AB7: =T7-SUM(O7:Q7)-Y7-AA7-Z7 -> 3808382 | AD7: =ROUNDUP(AB7,-3) -> 3809000 | AE7: =-harjono!K17 -> 0 | AF7: =SUM(AD7:AE7) -> 3809000 | AG7: =AF7-R7 -> 3809000
A8: 3 | B8: RAHMAT ARI SANDI NST | C8: herliana_81@yahoo.co.id | D8: 95.561.712.1-225.000 | E8: 2171122002829006 | F8: Batam | G8: Milling Operator | H8: K1 | I8: 1 | J8: 12 | K8: =rahmat!E14 -> 2000000 | L8: =rahmat!E15+rahmat!E17+rahmat!E22+rahmat!E16 -> 250000 | M8: =SUM(rahmat!E18:F21) -> 0 | N8: =-(rahmat!K14+rahmat!K19) -> -86000 | O8: =0.89%*K8 -> 17800 | P8: =4%*K8 -> 80000 | Q8: =0.3%*K8 -> 6000 | S8: =5.7%*K8 -> 114000 | T8: =ROUND(SUM(K8:R8),0) -> 2267800 | U8: =IFERROR(VLOOKUP(H8,TER!$B$4:$D$15,2,FALSE),"") -> B | V8: =SUMPRODUCT(TER!$K$4:$K$130*(TER!$G$4:$G$130=U8)*(TER!$H$4:$H$130<T8)*((TER!$J$4:$J$130>=T8)+(TER!$J$4:$J$130=""))) -> 0 | W8: =IFERROR(ROUND(T8*V8,0),"") -> 0 | Y8: =rahmat!K17 -> 60000 | Z8: =rahmat!K20 -> 20000 | AA8: =W8 -> 0 | AB8: =T8-SUM(O8:Q8)-Y8-AA8-Z8 -> 2084000 | AD8: =ROUNDUP(AB8,-3) -> 2084000 | AE8: =-rahmat!K18 -> 0 | AF8: =SUM(AD8:AE8) -> 2084000 | AG8: =AF8-R8 -> 2084000
K10: =SUM(K6:K9) -> 10000000 | L10: =SUM(L6:L9) -> 1390000 | M10: =SUM(M6:M9) -> 3424277.5 | N10: =SUM(N6:N9) -> -86000 | O10: =SUM(O6:O9) -> 134959.6 | P10: =SUM(P6:P9) -> 606560 | Q10: =SUM(Q6:Q9) -> 45492 | R10: =SUM(R6:R9) -> 0 | ... T10: =SUM(T6:T9) -> 15515290 | V10: =SUM(V6:V9) -> 0.01 | W10: =SUM(W6:W9) -> 91634 | Y10: =SUM(Y6:Y9) -> 454920 | Z10: =SUM(Z6:Z9) -> 151640 | AA10: =SUM(AA6:AA9) -> 91634 | AB10: =SUM(AB6:AB9) -> 14030084 | AD10: =SUM(AD6:AD9) -> 14031000 | AE10: =SUM(AE6:AE9) -> 0 | AF10: =SUM(AF6:AF9) -> 14031000
A28: TK | B28: 54000000
A29: K0 | B29: =+B28+4500000 -> 58500000
A30: K1 | B30: =+B29+4500000 -> 63000000
A31: K2 | B31: =+B30+4500000 -> 67500000
A32: K3 | B32: =+B31+4500000 -> 72000000

Sheet wawan
A1: PT. Mitra Karya Sarana
A2: Taiwan International Park Blok B No. 117
A3: Kabil, Nongsa - Batam Island
A5: SLIP GAJI
E6: Periode : Juli 2026
A8: Nama / NIK | B8: : | C8: Wawan Munandar | E8: MKS 0021 | G8: Perhari | H8: : | J8: =(E14+E15)/25 -> 204000
A9: Dept | B9: : | C9: Production | G9: Lembur/Jam | H9: : | J9: =(E14+E15)/173 -> 29479.769
A10: Jabatan | B10: : | C10: Supervisor | G10: T. Kehadiran | H10: : | J10: 10000
A12: PENGHASILAN | G12: PENGURANGAN
A14: Gaji Pokok | B14: : | E14: 5000000 | G14: Absent | H14: : | I14: =PRD!AJ140 -> 0 | J14: Hari | K14: =J8*I14 -> 0
A15: T.Tetap | B15: : | E15: 100000 | G15: PPh 21 | H15: : | K15: ='Daftar Gaji'!AA6 -> 91634
A16: T. Kehadiran | B16: : | C16: 27 | E16: =($J$10*C16) -> 270000 | G16: JHT+JP (2%+1%) | K16: =3%*10164000 -> 304920
A17: Lembur ( 1.5 ) | B17: : | C17: =PRD!AD140 -> 36 | E17: =$J$9*C17 -> 1061271.7
A18: Lembur ( 2 ) | B18: : | C18: =PRD!AE140 -> 68 | E18: =$J$9*C18 -> 2004624.3
A19: Lembur ( 3 ) | B19: : | C19: =PRD!AF140 -> 0 | E19: =$J$9*C19 -> 0 | G19: BPJS KESEHATAN 1% | K19: =1%*10164000 -> 101640
A20: Lembur ( 4 ) | B20: : | C20: =PRD!AG140 -> 0 | E20: =$J$9*C20 -> 0
A21: Insentive+ 2nd Shift | D21: 0 | E21: 200000
A22: JUMLAH | E22: =SUM(E14:F21) -> 8635896 | G22: JUMLAH | H22: : | K22: =SUM(K14:L19) -> 498194
G23: PENGHASILAN BERSIH | K23: =E22-K22 -> 8137702
G24: PEMBULATAN | K24: =ROUNDUP(K23,-3) -> 8138000
A26: Terbilang | B26: : | C26: =Inword!A8 -> Delapan Juta Seratus Tiga Puluh Delapan Ribu Rupiah
G28: Batam, 5 Agustus 2026
G29: Prepared By,
G30: HRD

Sheet harjono
A1: PT. Mitra Karya Sarana
A2: Taiwan International Park Blok B No. 117
A3: Kabil, Nongsa - Batam Island
A5: SLIP GAJI
E6: =wawan!E6 -> Periode : Juli 2026
A8: Nama / NIK | B8: : | C8: Harjono | E8: MKS 0013 | G8: Perhari | H8: : | J8: =(E14+E15)/25 -> 124000
A9: Dept | B9: : | C9: Production | G9: Lembur/Jam | H9: : | J9: =(E14+E15)/173 -> 17919.075
A10: Jabatan | B10: : | C10: Leader | G10: T. Kehadiran | H10: : | J10: 10000
A12: PENGHASILAN | G12: PENGURANGAN
A14: Gaji Pokok | B14: : | E14: 3000000 | G14: Absent | H14: : | I14: =PRD!AJ47 -> 0 | J14: Hari | K14: =J8*I14 -> 0
A15: T.Tetap | E15: 100000 | G15: PPh 21 | H15: : | K15: ='Daftar Gaji'!AA7 -> 0
A16: T. Kehadiran | B16: : | C16: 27 | E16: =($J$10*C16) -> 270000 | G16: JHT+JP (2%+1%) | K16: =3%*E14 -> 90000
A17: Lembur ( 1.5 ) | B17: : | C17: =PRD!AD47 -> 12 | E17: =$J$9*C17 -> 215028.9 | G17: Pinjaman | H17: : | K17: 0
A18: Lembur ( 2 ) | B18: : | C18: =PRD!AE47 -> 8 | E18: =$J$9*C18 -> 143352.6 | G18: Absent | H18: : | I18: =PRD!AI47 -> 0 | J18: Jam | K18: =J9*I18 -> 0
A19: Lembur ( 3 ) | B19: : | C19: =PRD!AF47 -> 0 | E19: =$J$9*C19 -> 0 | G19: BPJS KESEHATAN 1% | K19: =1%*E14 -> 30000
A20: Lembur ( 4 ) | B20: : | C20: =PRD!AG47 -> 0 | E20: =$J$9*C20 -> 0
A21: Insentive+ 2nd Shift | D21: 0 | E21: 200000
A22: JUMLAH | E22: =SUM(E14:F21) -> 3928381.5 | G22: JUMLAH | H22: : | K22: =SUM(K14:L19) -> 120000
G23: PENGHASILAN BERSIH | K23: =E22-K22 -> 3808381.5
G24: PEMBULATAN | K24: =ROUNDUP(K23,-3) -> 3809000
A26: Terbilang | B26: : | C26: =Inword!A110 -> Tiga Juta Delapan Ratus Sembilan Ribu Rupiah
G28: =wawan!G28 -> Batam, 5 Agustus 2026
G29: Prepared By,
G30: HRD

Sheet rahmat
A1: PT. Mitra Karya Sarana
A2: Taiwan International Park Blok B No. 117
A3: Kabil, Nongsa - Batam Island
A5: SLIP GAJI
E6: =wawan!E6 -> Periode : Juli 2026
A8: Nama / NIK | B8: : | C8: Rahmat Ari Sandi NST | E8: MKS 0020 | G8: Perhari | H8: : | J8: =(E14+E15)/25 -> 86000
A9: Dept | B9: : | C9: Production | G9: Lembur/Jam | H9: : | J9: =(E14+E15)/173 -> 12427.746
A10: Jabatan | B10: : | C10: Milling Operator | G10: T. Kehadiran | H10: : | J10: 10000
G11: T. Transport | H11: : | J11: 10000
A12: PENGHASILAN | G12: PENGURANGAN
A14: Gaji Pokok | B14: : | E14: 2000000 | G14: Absent | H14: : | I14: 1 | J14: Hari | K14: =J8*I14 -> 86000
A15: T.Tetap | B15: : | E15: 150000 | G15: PPh 21 | H15: : | K15: ='Daftar Gaji'!AA8 -> 0
A16: T. Transport | B16: : | C16: 5 | E16: =C16*J11 -> 50000
A17: T. Kehadiran | B17: : | C17: 5 | E17: =C17*J10 -> 50000 | G17: JHT+JP (2%+1%) | K17: =3%*E14 -> 60000
A18: Lembur ( 1.5 ) | B18: : | C18: =PRD!AD94 -> 0 | E18: =$J$9*C18 -> 0
A19: Lembur ( 2 ) | B19: : | C19: =PRD!AE94 -> 0 | E19: =$J$9*C19 -> 0 | G19: Absent | H19: : | I19: =PRD!AI94 -> 0 | J19: Jam | K19: =J9*I19 -> 0
A20: Lembur ( 3 ) | B20: : | C20: =PRD!AF94 -> 0 | E20: =$J$9*C20 -> 0 | G20: BPJS KESEHATAN 1% | K20: =1%*E14 -> 20000
A21: Lembur ( 4 ) | B21: : | C21: =PRD!AG94 -> 0 | E21: =$J$9*C21 -> 0
A22: Insentive+ 2nd Shift | D22: 0 | E22: 0
A23: JUMLAH | E23: =SUM(E14:F22) -> 2250000 | G23: JUMLAH | H23: : | K23: =SUM(K14:L20) -> 166000
G24: PENGHASILAN BERSIH | K24: =E23-K23 -> 2084000
G25: PEMBULATAN | K25: =ROUNDUP(K24,-3) -> 2084000
A27: Terbilang | B27: : | C27: =Inword!A620 -> Dua Juta Delapan Puluh Empat Ribu Rupiah
G29: =wawan!G28 -> Batam, 5 Agustus 2026
G30: Prepared By,
G31: HRD

Sheet TER
B3: Status | C3: Kategori | D3: PTKP | E3: Bulanan | G3: Jenis TER | H3: Penghasilan Bruto | K3: TER
B4: TK | C4: A | D4: =E4*12 -> 54000000 | E4: 4500000 | G4: A | H4: 0 | I4: s.d | J4: 5400000 | K4: 0
B5: TK1 | C5: A | D5: =D4+$E$4 -> 58500000 | G5: A | H5: =J4 -> 5400000 | I5: s.d | J5: 5650000 | K5: 0.0025
B6: TK2 | C6: B | D6: =D5+$E$4 -> 63000000 | G6: A | H6: =J5 -> 5650000 | I6: s.d | J6: 5950000 | K6: 0.005
B7: TK3 | C7: B | D7: =D6+$E$4 -> 67500000 | G7: A | H7: =J6 -> 5950000 | I7: s.d | J7: 6300000 | K7: 0.0075
B8: K0 | C8: A | D8: =D5 -> 58500000 | G8: A | H8: =J7 -> 6300000 | I8: s.d | J8: 6750000 | K8: 0.01
B9: K1 | C9: B | D9: =D8+$E$4 -> 63000000 | G9: A | H9: =J8 -> 6750000 | I9: s.d | J9: 7500000 | K9: 0.0125
B10: K2 | C10: B | D10: =D9+$E$4 -> 67500000 | G10: A | H10: =J9 -> 7500000 | I10: s.d | J10: 8550000 | K10: 0.015
B11: K3 | C11: C | D11: =D10+$E$4 -> 72000000 | G11: A | H11: =J10 -> 8550000 | I11: s.d | J11: 9650000 | K11: 0.0175
G12: A | H12: =J11 -> 9650000 | I12: s.d | J12: 10050000 | K12: 0.02
G13: A | H13: =J12 -> 10050000 | I13: s.d | J13: 10350000 | K13: 0.0225
G14: A | H14: =J13 -> 10350000 | I14: s.d | J14: 10700000 | K14: 0.025
G15: A | H15: =J14 -> 10700000 | I15: s.d | J15: 11050000 | K15: 0.03
G16: A | H16: =J15 -> 11050000 | I16: s.d | J16: 11600000 | K16: 0.035
G17: A | H17: =J16 -> 11600000 | I17: s.d | J17: 12500000 | K17: 0.04
G18: A | H18: =J17 -> 12500000 | I18: s.d | J18: 13750000 | K18: 0.05
G19: A | H19: =J18 -> 13750000 | I19: s.d | J19: 15100000 | K19: 0.06
G20: A | H20: =J19 -> 15100000 | I20: s.d | J20: 16950000 | K20: 0.07
G21: A | H21: =J20 -> 16950000 | I21: s.d | J21: 19750000 | K21: 0.08
G22: A | H22: =J21 -> 19750000 | I22: s.d | J22: 24150000 | K22: 0.09
G23: A | H23: =J22 -> 24150000 | I23: s.d | J23: 26450000 | K23: 0.1
... G46: A | H46: =J45 -> 910000000 | I46: s.d | J46: 1400000000 | K46: 0.33
G47: A | H47: 1400000000 | K47: 0.34
G48: B | H48: 0 | I48: s.d | J48: 6200000 | K48: 0
G49: B | H49: =J48 -> 6200000 | I49: s.d | J49: 6500000 | K49: 0.0025
G50: B | H50: =J49 -> 6500000 | I50: s.d | J50: 6850000 | K50: 0.005
G51: B | H51: =J50 -> 6850000 | I51: s.d | J51: 7300000 | K51: 0.0075
G52: B | H52: =J51 -> 7300000 | I52: s.d | J52: 9200000 | K52: 0.01
G53: B | H53: =J52 -> 9200000 | I53: s.d | J53: 10750000 | K53: 0.015
G54: B | H54: =J53 -> 10750000 | I54: s.d | J54: 11250000 | K54: 0.02
G55: B | H55: =J54 -> 11250000 | I55: s.d | J55: 11600000 | K55: 0.025
G56: B | H56: =J55 -> 11600000 | I56: s.d | J56: 12600000 | K56: 0.03
G57: B | H57: =J56 -> 12600000 | I57: s.d | J57: 13600000 | K57: 0.04
G58: B | H58: =J57 -> 13600000 | I58: s.d | J58: 14950000 | K58: 0.05
G59: B | H59: =J58 -> 14950000 | I59: s.d | J59: 16400000 | K59: 0.06
G60: B | H60: =J59 -> 16400000 | I60: s.d | J60: 18450000 | K60: 0.07
... G86: B | H86: =J85 -> 957000000 | I86: s.d | J86: 1405000000 | K86: 0.33
G87: B | H87: 1405000000 | K87: 0.34
G88: C | H88: 0 | I88: s.d | J88: 6600000 | K88: 0
G89: C | H89: =J88 -> 6600000 | I89: s.d | J89: 6950000 | K89: 0.0025
...

Sheet Inword
A1: =wawan!K24 -> 8138000 | C1: WAWAN
J3: 0 | K3: Zero | L3: Nol
J4: 1 | K4: One | L4: Satu
A5: =TRIM(D13&E13&D14&E14&D15&E15&D16&E16&D17&E17&D18&E18&E19&D19&" Only") -> Eight Millions One Hundred Thirty Eight Thousands Only | J5: 2 | K5: Two | L5: Dua
J6: 3 | K6: Three | L6: Tiga
J7: 4 | K7: Four | L7: Empat
A8: =TRIM(D23&E23&D24&E24&D25&E25&D26&E26&D27&E27&D28&E28&D29&E29&" Rupiah") -> Delapan Juta Seratus Tiga Puluh Delapan Ribu Rupiah | J8: 5 | K8: Five | L8: Lima
J9: 6 | K9: Six | L9: Enam
J10: 7 | K10: Seven | L10: Tujuh
J11: 8 | K11: Eight | L11: Delapan
A12: BAHASA ENGLISH | J12: 9 | K12: Nine | L12: Sembilan
A13: ratusan juta | B13: =TRUNC(A1/100000000) -> 0 | C13: =B13*100000000 -> 0 | D13: =IF(B13<1,"",VLOOKUP(B13,$J$3:$K$102,2)) | E13: =IF(B13<1,"",IF(B13>1," Hundreds "," Hundred ")) | J13: 10 | K13: Ten | L13: Sepuluh
A14: puluhan juta | B14: =TRUNC((A1-C13)/1000000) -> 8 | C14: =B14*1000000 -> 8000000 | D14: =IF(B14<1,"",VLOOKUP(B14,$J$3:$K$102,2)) -> Eight | E14: =IF(B13+B14=0,"",IF(B14=1," Million "," Millions ")) -> Millions | J14: 11 | K14: Eleven | L14: Sebelas
A15: ratusan ribu | B15: =TRUNC((A1-SUM(C13:C14))/100000) -> 1 | C15: =B15*100000 -> 100000 | D15: =IF(B15<1,"",VLOOKUP(B15,$J$3:$K$102,2)) -> One | E15: =IF(B15<1,"",IF(B15>1," Hundreds "," Hundred ")) -> Hundred | J15: 12 | K15: Twelve | L15: =L5&" Belas" -> Dua Belas
A16: ribuan | B16: =TRUNC((A1-SUM(C13:C15))/1000) -> 38 | C16: =B16*1000 -> 38000 | D16: =IF(B16<1,"",VLOOKUP(B16,$J$3:$K$102,2)) -> Thirty Eight | E16: =IF(B15+B16=0,"",IF(B16=1," Thousand "," Thousands ")) -> Thousands | J16: 13 | K16: Thirteen | L16: =L6&" Belas" -> Tiga Belas
A17: ratusan | B17: =TRUNC((A1-SUM(C13:C16))/100) -> 0 | C17: =B17*100 -> 0 | D17: =IF(B17<1,"",VLOOKUP(B17,$J$3:$K$102,2)) | E17: =IF(B17<1,"",IF(B17>1," Hundreds "," Hundred ")) | J17: 14 | K17: Fourteen | L17: =L7&" Belas" -> Empat Belas
A18: puluhan | B18: =TRUNC((A1-SUM(C13:C17))) -> 0 | C18: =B18 -> 0 | D18: =IF(B18<1,"",VLOOKUP(B18,$J$3:$K$102,2)) | E18: =IF(SUM(C13:C18)<1,"",IF(B19<1,""," And ")) | J18: 15 | K18: Fifteen | L18: =L8&" Belas" -> Lima Belas
A19: cents | B19: =ROUND(A1-SUM(C13:C18),2)*100 -> 0 | D19: =IF(B19<1,"",VLOOKUP(B19,$J$3:$K$102,2)) | E19: =IF(B19<1,"",IF(B19=1," Cent "," Cents ")) | J19: 16 | K19: Sixteen | L19: =L9&" Belas" -> Enam Belas
J20: 17 | K20: Seventeen | L20: =L10&" Belas" -> Tujuh Belas
J21: 18 | K21: Eightteen | L21: =L11&" Belas" -> Delapan Belas
A22: BAHASA INDONSIA | J22: 19 | K22: Nineteen | L22: =L12&" Belas" -> Sembilan Belas
A23: ratusan juta | B23: =TRUNC(A1/100000000) -> 0 | C23: =B23*100000000 -> 0 | D23: =IF(B23<1,"",IF(B23=1,"",VLOOKUP(B23,$J$3:$L$102,3))) | E23: =IF(B23<1,"",IF(B23=1,"Seratus "," Ratus ")) | J23: 20 | K23: Twenty | L23: Dua Puluh
A24: puluhan juta | B24: =TRUNC((A1-C23)/1000000) -> 8 | C24: =B24*1000000 -> 8000000 | D24: =IF(B24<1,"",VLOOKUP(B24,$J$3:$L$102,3)) -> Delapan | E24: =IF(B23+B24=0,""," Juta ") -> Juta | J24: 21 | K24: Twenty One | L24: =$L$23&" "&L4 -> Dua Puluh Satu
A25: ratusan ribu | B25: =TRUNC((A1-SUM(C23:C24))/100000) -> 1 | C25: =B25*100000 -> 100000 | D25: =IF(B25<1,"",IF(B25=1,"",VLOOKUP(B25,$J$3:$L$102,3))) | E25: =IF(B25<1,"",IF(B25=1," Seratus "," Ratus ")) -> Seratus | J25: 22 | K25: Twenty Two | L25: =$L$23&" "&L5 -> Dua Puluh Dua
A26: ribuan | B26: =TRUNC((A1-SUM(C23:C25))/1000) -> 38 | C26: =B26*1000 -> 38000 | D26: =IF(B26<1,"",IF(B26=1,"",VLOOKUP(B26,$J$3:$L$102,3))) -> Tiga Puluh Delapan | E26: =IF(B25+B26<1,"",IF(B26=1," Seribu "," Ribu ")) -> Ribu | J26: 23 | K26: Twenty Three | L26: =$L$23&" "&L6 -> Dua Puluh Tiga
A27: ratusan | B27: =TRUNC((A1-SUM(C23:C26))/100) -> 0 | C27: =B27*100 -> 0 | D27: =IF(B27<1,"",IF(B27=1,"",VLOOKUP(B27,$J$3:$L$102,3))) | E27: =IF(B27<1,"",IF(B27=1," Seratus "," Ratus ")) | J27: 24 | K27: Twenty Four | L27: =$L$23&" "&L7 -> Dua Puluh Empat
A28: puluhan | B28: =TRUNC((A1-SUM(C23:C27))) -> 0 | C28: =B28 -> 0 | D28: =IF(B28<1,"",VLOOKUP(B28,$J$3:$L$102,3)) | E28: =IF(SUM(C23:C28)<1,"",IF(B29<1,""," Dan ")) | J28: 25 | K28: Twenty Five | L28: =$L$23&" "&L8 -> Dua Puluh Lima
A29: cents | B29: =ROUND(A1-SUM(C23:C28),2)*100 -> 0 | D29: =IF(B29<1,"",VLOOKUP(B29,$J$3:$L$102,3)) | E29: =IF(B29<1,""," Sen ") | J29: 26 | K29: Twenty Six | L29: =$L$23&" "&L9 -> Dua Puluh Enam
J30: 27 | K30: Twenty Seven | L30: =$L$23&" "&L10 -> Dua Puluh Tujuh
J31: 28 | K31: Twenty Eight | L31: =$L$23&" "&L11 -> Dua Puluh Delapan
J32: 29 | K32: Twenty Nine | L32: =$L$23&" "&L12 -> Dua Puluh Sembilan
J33: 30 | K33: Thirty | L33: Tiga Puluh
J34: 31 | K34: Thirty One | L34: =$L$33&" "&L4 -> Tiga Puluh Satu
J35: 32 | K35: Thirty Two | L35: =$L$33&" "&L5 -> Tiga Puluh Dua
J36: 33 | K36: Thirty Three | L36: =$L$33&" "&L6 -> Tiga Puluh Tiga
J37: 34 | K37: Thirty Four | L37: =$L$33&" "&L7 -> Tiga Puluh Empat
J38: 35 | K38: Thirty Five | L38: =$L$33&" "&L8 -> Tiga Puluh Lima
J39: 36 | K39: Thirty Six | L39: =$L$33&" "&L9 -> Tiga Puluh Enam
J40: 37 | K40: Thirty Seven | L40: =$L$33&" "&L10 -> Tiga Puluh Tujuh
J41: 38 | K41: Thirty Eight | L41: =$L$33&" "&L11 -> Tiga Puluh Delapan
...

Sheet PRD
I1: Laporan Detail Harian
B4: No. ID
F5: 10013
A9: Nama
F10: HARJONO
A14: Tanggal | H14: Jam Masuk | K14: Jam Pulang | N14: Scan Masuk | P14: Scan Keluar | Q14: Terlambat | R14: Plg Cpt | T14: Lembur | W14: Jam Kerja | Z14: Jml Hadir | AD14: X1,5 | AE14: X2 | AF14: X3 | AG14: X4 | AH14: Deduct | AI14: Total | AJ14: Absen
A16: 46204 | H16: 0.32291667 | K16: 0.66666667 | N16: 0.30138889 | P16: 0.68402778 | T16: 0.010416667 | W16: 0.35069444 | Z16: 0.38263889
A17: 46205 | N17: 0.30416667 | P17: 0.68055556 | T17: 0.0069444444 | W17: 0.35069444 | Z17: 0.37569444
A18: 46206 | H18: 0.32291667 | K18: 0.625 | N18: 0.30277778 | P18: 0.7625 | T18: 0.088888889 | W18: 0.35069444 | Z18: 0.45972222 | AD18: 1 | AE18: 1
A19: 46207 | H19: 0.32291667 | K19: 0.66666667 | N19: 0.29861111 | P19: 0.68263889 | T19: 0.050694444 | W19: 0.30902778 | Z19: 0.38333333 | AD19: 1
A20: 46208 | H20: 0.32291667 | K20: 0.66666667
A21: 46209 | H21: 0.32291667 | K21: 0.66666667 | N21: 0.30555556 | P21: 0.69513889 | T21: 0.021527778 | W21: 0.35069444 | Z21: 0.38888889
A22: 46210 | H22: 0.32291667 | K22: 0.66666667 | N22: 0.29722222 | P22: 0.68888889 | T22: 0.015277778 | W22: 0.35069444 | Z22: 0.39166667
A23: 46211 | H23: 0.32291667 | K23: 0.66666667 | N23: 0.30972222 | P23: 0.68402778 | T23: 0.010416667 | W23: 0.35069444 | Z23: 0.37361111
A24: 46212 | N24: 0.30347222 | P24: 0.68333333 | T24: 0.0097222222 | W24: 0.35069444 | Z24: 0.37986111
A25: 46213 | N25: 0.30277778 | P25: 0.68888889 | T25: 0.015277778 | W25: 0.35069444 | Z25: 0.38611111
A26: 46214 | N26: 0.30069444 | P26: 0.69166667 | T26: 0.059722222 | W26: 0.30902778 | Z26: 0.39027778 | AD26: 1
A27: 46215
A28: 46216 | H28: 0.32291667 | K28: 0.66666667 | N28: 0.29513889 | P28: 0.78611111 | T28: 0.1125 | W28: 0.35069444 | Z28: 0.49027778 | AD28: 1 | AE28: 1
A29: 46217 | H29: 0.32291667 | K29: 0.625 | N29: 0.3 | P29: 0.68402778 | T29: 0.010416667 | W29: 0.35069444 | Z29: 0.38402778
A30: 46218 | H30: 0.32291667 | K30: 0.66666667 | N30: 0.30069444 | P30: 0.68888889 | T30: 0.015277778 | W30: 0.35069444 | Z30: 0.38819444
A31: 46219 | H31: 0.32291667 | K31: 0.66666667 | N31: 0.29722222 | P31: 0.68263889 | T31: 0.0090277778 | W31: 0.35069444 | Z31: 0.38541667
A32: 46220 | H32: 0.32291667 | K32: 0.66666667 | N32: 0.29930556 | P32: 0.76180556 | T32: 0.088194444 | W32: 0.35069444 | Z32: 0.4625 | AD32: 1 | AE32: 1
A33: 46221 | H33: 0.32291667 | K33: 0.66666667 | N33: 0.30625 | P33: 0.68402778 | T33: 0.052083333 | W33: 0.30902778 | Z33: 0.37708333 | AD33: 1
A34: 46222 | H34: 0.32291667 | K34: 0.66666667
A35: 46223 | H35: 0.32291667 | K35: 0.66666667 | N35: 0.30208333 | P35: 0.68333333 | T35: 0.0097222222 | W35: 0.35069444 | Z35: 0.38055556
A36: 46224 | H36: 0.32291667 | K36: 0.625 | N36: 0.30486111 | P36: 0.68819444 | T36: 0.014583333 | W36: 0.35069444 | Z36: 0.38263889
A37: 46225 | H37: 0.32291667 | K37: 0.66666667 | N37: 0.3 | P37: 0.68194444 | T37: 0.0083333333 | W37: 0.35069444 | Z37: 0.38194444
A38: 46226 | H38: 0.32291667 | K38: 0.66666667 | N38: 0.30138889 | P38: 0.7 | T38: 0.026388889 | W38: 0.35069444 | Z38: 0.39861111
A39: 46227 | H39: 0.32291667 | K39: 0.66666667 | N39: 0.30069444 | P39: 0.70972222 | T39: 0.036111111 | W39: 0.35069444 | Z39: 0.40833333
A40: 46228 | N40: 0.30277778 | P40: 0.69722222 | T40: 0.065277778 | W40: 0.30902778 | Z40: 0.39375 | AD40: 1
A41: 46229
A42: 46230 | N42: 0.3 | P42: 0.7 | T42: 0.026388889 | W42: 0.35069444 | Z42: 0.39930556
A43: 46231 | N43: 0.30347222 | R43: 0.041666667 | W43: 0.30902778 | Z43: 0.36944444 | AD43: 1 | AE43: 1
A44: 46232 | N44: 0.29861111 | P44: 0.69722222 | T44: 0.023611111 | W44: 0.35069444 | Z44: 0.39861111
A45: 46233 | N45: 0.30625 | P45: 0.69166667 | T45: 0.018055556 | W45: 0.35069444 | Z45: 0.38541667
A46: 46234 | N46: 0.30208333 | P46: 0.68958333 | T46: 0.015972222 | W46: 0.35069444 | Z46: 0.3875
AD47: =SUM(AD16:AD46)*1.5 -> 12 | AE47: =SUM(AE16:AE46)*2 -> 8 | AF47: =SUM(AF16:AF46)*3 -> 0 | AG47: =SUM(AG16:AG46)*4 -> 0 | AH47: =SUM(AH16:AH46) -> 0 | AI47: =AH47/60 -> 0 | AJ47: =SUM(AJ16:AJ46) -> 0
C48: Oleh: | G48: Supervisor
E49: 25/04/2014
...
